Workbook

Sheet REKAP
B1: https://docs.google.com/spreadsheets/d/1r7Tu4i1wdGSE1v7PLLbL4LHgrkp8S3KHqOdmaCZaZpc/edit?usp=sharing
A3: No | B3: Nama Sekolah | C3: Kab/Kota | D3: PIC SEKOLAH | E3: Jumlah Rombel | F3: Nilai PO SETELAH PAJAK | G3: Link Drive SP | H3: Link Drive MOU | I3: Accurate | J3: Partisipasi Grup | K3: EMAIL PO DARI MM KE PE | L3: Link Pengumpulan data Akun guru dan siswa | M3: Catatan Kekurangan | N3: Tindak Lanjut | O3: FIX TL | P3: Tanggal terakhir komunikasi dan keterangan | Q3: LINK AKUN SIAP PAKAI | R3: Kirim ke sekolah | S3: Check List Data | T3: email MM-PE | U3: Tanggal Kirim email dari PE | V3: JADWAL PELATIHAN | W3: MATERI PELATIHAN | X3: Monitoring
A4: 1 | B4: SMAN 1 Kajen | C4: Kab. Pekalongan | D4: 81901001447 | E4: 33 | F4: 55962315 | G4: SMA N 1 Kajen.pdf | I4: FALSE | J4: TRUE | K4: 46226 | L4: https://docs.google.com/spreadsheets/d/19uA2-ByCW_lBVA7EBeCfiPwTz7s2JuKktawmhRTiCvk/edit?usp=sharing | M4: 0. masih ada 44 slot akun guru 0. masih ada 9 slot akun siswa | N4: dibuatkan akun dummy | O4: FALSE | P4: 46181 | R4: FALSE | S4: BELUM LENGKAP | T4: TRUE | V4: 46302
A5: 2 | B5: SMAN 1 Ambarawa | C5: Kab Semarang | D5: 82138231186 | E5: 24 | F5: 61050000 | G5: SMA N 1 Ambarawaa.pdf | I5: FALSE | J5: TRUE | K5: 46227 | L5: https://docs.google.com/spreadsheets/d/1tHbodaY3rzCzbjoKzmm_R3g4xjQ_qpw7XZXiCFwYbLs/edit?usp=sharing | M5: 0. masih ada slot 57 akun guru 0. masih ada slot 13 akun siswa | N5: dibuatkan akun dummy | O5: FALSE | P5: 07/08/2026. | R5: FALSE | S5: TOLERANSI | T5: TRUE | U5: 46218 | V5: 14/08/2026
A6: 3 | B6: SMAN 10 Semarang | C6: Kota Semarang | D6: +62 812-2575-325 (Bapak Supriyadi) | E6: 20 | F6: 50875185 | G6: SMA N 10 Semarang.pdf | I6: FALSE | J6: TRUE | K6: 46229 | L6: https://docs.google.com/spreadsheets/d/1mHTiiv7rN8rSPomUSz-RvGAvOEJyd4br1C_GOPS4djM/edit?usp=sharing | M6: 0. masih ada 15 slot akun guru 0. akun siswa terlebih 23 | N6: dibuatkan akun dummy dan dilebihkan 23 | O6: FALSE | P6: 04/08/2026. | R6: FALSE | S6: TOLERANSI | T6: TRUE | U6: 46241 | V6: 46241
A7: 4 | B7: SMAN 11 Semarang | C7: Kota Semarang | D7: +62 821-3898-2222 (Bapak Rifai) | E7: 24 | F7: 61050000 | G7: SMA N 11 Semarang.pdf | I7: TRUE | J7: TRUE | K7: 46229 | L7: https://docs.google.com/spreadsheets/d/151Y6gM_APFv5ey-gXSZqrTc4XonbeP1hs3Rd6OZnXjU/edit?usp=sharing | M7: 1. admin wakur belum ada 0. masih ada 11 slot akun guru dan 4 slot akun siswa 0. data siswa (email dan asesmen belum ada) | N7: akun admin wakur : email sekolah dibuatkan akun dummy email siswa : email sekolah asesmen : 30 agustus | O7: FALSE | P7: 06/08/2026. | R7: TRUE | S7: BELUM LENGKAP | T7: TRUE | U7: 46272 | V7: 46272
A8: 5 | B8: SMAN 2 Ungaran | C8: Kab Semarang | D8: 89634462944 (PAK ANIS NASIKIN) | E8: 24 | F8: 61050000 | G8: SMA N 2 Ungaran.pdf | I8: FALSE | J8: TRUE | K8: 46227 | L8: https://docs.google.com/spreadsheets/d/1YNG2etyQ0fR9wrCbXVxjZ6fbX4VKOCJjdFmes28Tts0/edit?usp=sharing | M8: 0. masih ada 17 slot akun guru 0. tanggal asesmen belum ada | N8: 0. akun dummy 0. tanggal asesmen : 30 agustus | O8: FALSE | P8: 46181 | Q8: https://docs.google.com/spreadsheets/d/1U8Xb9df3Jre49XFfCqNHhAwLnlq5cJVG/edit?usp=drive_link&ouid=115389489815414373079&rtpof=true&sd=true | R8: FALSE | S8: BELUM LENGKAP | T8: TRUE | U8: 30-06-2026 | V8: 46303
A9: 6 | B9: SMAN 1 Klaten | C9: Kab. Klaten | D9: +62 815-1078-5965 (Bapak Febri) | E9: 11 | F9: 27981435 | G9: https://drive.google.com/file/d/1a6Bzbx5zaAHqg7AU3cCPTjp9t8NtQE61/view?usp=drive_link | I9: FALSE | J9: TRUE | K9: 46226 | L9: https://docs.google.com/spreadsheets/d/1fgRkqFcZCFxxpVLq4RUFYEEyAj5gn0iLBTShNVLurKY/edit?gid=1298931778#gid=1298931778 | M9: 0. masih ada 2 slot akun siswa | N9: dibuatkan akun dummy | O9: FALSE | P9: 46181 | Q9: https://docs.google.com/spreadsheets/d/1YqEPVEC40vdEXaxoQp1BY4FfLLOXMfWy/edit?usp=drive_link&ouid=115389489815414373079&rtpof=true&sd=true | R9: FALSE | S9: TOLERANSI | T9: TRUE | V9: 31/07/2026
A10: 7 | B10: SMAN 2 Klaten | C10: Kab. Klaten | D10: 85773218628 | E10: 10 | F10: 25437315 | G10: https://drive.google.com/file/d/1r2EyurTSP3ZQr7oGHbTomgdw75dZPMmP/view?usp=drive_link | I10: FALSE | J10: TRUE | K10: 46227 | L10: https://docs.google.com/spreadsheets/d/12mvKn4_XHL2aA15_3bpNoyup1MUfLzu613HApbA7mjs/edit?usp=sharing | M10: 0. masih ada 2 slot akun guru | N10: dibuatkan akun dummy | O10: FALSE | P10: 46181 | Q10: https://docs.google.com/spreadsheets/d/1HYQ8ZKisBlzODkV-icmVZXxMDEKm7YKK/edit?usp=drive_link&ouid=115389489815414373079&rtpof=true&sd=true | R10: FALSE | S10: BELUM LENGKAP | T10: TRUE | V10: 46120
A11: 8 | B11: SMAN 3 Klaten | C11: Kab. Klaten | D11: 081364776941 (Bu Santi) | E11: 10 | F11: 25437315 | G11: https://drive.google.com/file/d/1T1FYbjH7tdgISy0qfcUjoVT3DxsVyX9h/view?usp=drive_link | I11: FALSE | J11: TRUE | K11: 46227 | L11: https://docs.google.com/spreadsheets/d/1Dewz76vNjp8mx5ivtyNk4AJ0Kflanw4sVGAWEHRgvUg/edit?usp=sharing | M11: 0. akun guru terlebih 3 masih ada 4 slot siswa | N11: dilebihkan 3 akun guru dibuatkan akun dummy | O11: FALSE | P11: 46181 | Q11: https://docs.google.com/spreadsheets/d/1NPuS0U4gHPlr_ABsDpcwzWe18kbCd-6H/edit?usp=drive_link&ouid=115389489815414373079&rtpof=true&sd=true | R11: FALSE | S11: TOLERANSI | T11: TRUE | V11: 30/07/2026
A12: 9 | B12: SMAN 1 Sragi | C12: Kab. Pekalongan | D12: 85647003083 | E12: 18 | F12: 45787500 | G12: SMA N 1 Sragi.pdf | I12: FALSE | J12: TRUE | K12: 46226 | L12: https://docs.google.com/spreadsheets/d/10c00zNoncvANOVtcljBjZSfkJ-Tr95scTIrRHep_NzM/edit?gid=1298931778#gid=1298931778 | M12: 0. masih ada 4 slot akun guru 0. masih ada 10 slot akun siswa | N12: akun dummy | O12: FALSE | P12: 46181 | Q12: https://docs.google.com/spreadsheets/d/1hCRJvWmdEywLlwvOrSeScp3gCbVTIFvR/edit?usp=drive_link&ouid=115389489815414373079&rtpof=true&sd=true | R12: FALSE | S12: BELUM LENGKAP | T12: TRUE | V12: 46364
A13: 10 | B13: SMAN 3 Surakarta | C13: Kota Surakarta | D13: 085728306060 (bp wardi) | E13: 12 | F13: 30525000 | G13: SMA N 3 Surakarta.pdf | I13: FALSE | J13: TRUE | K13: 46227 | L13: https://docs.google.com/spreadsheets/d/1Ki-O31v2ore93FlexUeYU4zgJLB-EwZKotjMYG-POmk/edit?usp=sharing | M13: 1. Terdapat akun guru yang belum ada emailnya 2. Masih ada 10 slot akun guru, 5 slot akun siswa | N13: email : email sekolah dibuatkan akun dummy | O13: FALSE | P13: 46211 | Q13: https://docs.google.com/spreadsheets/d/1M8DGcsN_JhBHkhedqJv8OpoO6Ks5FKeV/edit?usp=drive_link&ouid=115389489815414373079&rtpof=true&sd=true | R13: FALSE | S13: BELUM LENGKAP | T13: TRUE | V13: 23/07/2026
A14: 11 | B14: SMAN 1 Purwokerto | C14: Kab. Banyumas | D14: 8122745600 | E14: 22 | F14: 55962315 | G14: SMA N 1 Purwokerto.pdf | I14: FALSE | J14: TRUE | K14: 46226 | L14: https://docs.google.com/spreadsheets/d/159MKMbgreMHgQMkajSN-i9DUDJk0VhVMB-dRky17sXY/edit?usp=sharing | M14: 0. masih ada 10 slot akun guru 0. masih ada 1 slot akun siswa 0. tanggal asesmen (agustus) | N14: 0. akun dummy 0. tanggal asesmen (agustus) | O14: FALSE | Q14: https://docs.google.com/spreadsheets/d/1K9tOvPbQtQiloPAa7hFWVwT1zZCZQ80V/edit?usp=drive_link&ouid=115389489815414373079&rtpof=true&sd=true | R14: FALSE | S14: BELUM LENGKAP | T14: TRUE | V14: 27/07/2026
A15: 12 | B15: SMAN 2 Purbalingga | C15: Kab. Purbalingga | D15: 85709065758 | E15: 20 | F15: 50875185 | G15: SMA N 2 Purbalingga.pdf | I15: FALSE | J15: TRUE | K15: 46224 | L15: https://docs.google.com/spreadsheets/d/1gmy2G66z58lWUnUG4XxaOwSUo4pNyPnT4cxGXWpqoac/edit?usp=sharing | M15: 0. akun admin wakur 0. masih ada 13 slot akun guru 0. masih ada 4 slot akun siswa 0. tanggal pelaksanaan asesmen | N15: akun admin wakur = email sekolah akun dummy tanggal asesmen = agustus | O15: FALSE | P15: 46181 | Q15: https://docs.google.com/spreadsheets/d/1EEOjmJRfn9esr7Obwuo0kufzF0z-t-At/edit?usp=drive_link&ouid=115389489815414373079&rtpof=true&sd=true | R15: FALSE | S15: TOLERANSI | T15: TRUE | U15: 23 Juli 2026 | V15: 46089
A16: 13 | B16: SMAN 1 REMBANG | C16: Kab. Purbalingga | D16: 85799986356 | E16: 16 | F16: 40699815 | G16: SMA N 1 Rembang Purbalingga.pdf | I16: FALSE | J16: TRUE | K16: 46227 | L16: https://docs.google.com/spreadsheets/d/1PRWvnRrk0q_BjhM55ryS9c_3WQKO-AyHaCZVEky-S-c/edit?usp=sharing | M16: 1. masih ada 31 slot akun guru | O16: FALSE | Q16: https://docs.google.com/spreadsheets/d/1Calqf5albGcoJxUEIXr0eb36q-ZSoX5M/edit?usp=drive_link&ouid=115389489815414373079&rtpof=true&sd=true | R16: FALSE | S16: TOLERANSI | T16: TRUE | V16: 46089
A17: 14 | B17: SMAN 1 KUTASARI | C17: Kab. Purbalingga | D17: +62 856-4783-9157 | E17: 14 | F17: 35612685 | G17: SMA N 1 Kutasari.pdf | I17: FALSE | J17: TRUE | K17: 46226 | L17: https://docs.google.com/spreadsheets/d/1D9bsG-2u_MQusmnwBmJkfdT_w4yLFcpF3OpTTeyAzys/edit?gid=466295844#gid=466295844 | M17: 3. akun asesmen (email siswa dan tanggal) 0. masih ada 8 slot akun guru 0. masih ada 4 slot akun siswa | N17: 3. email siswa : email sekolah, tanggal agustus 0. dummy | O17: FALSE | P17: 46181 | Q17: https://docs.google.com/spreadsheets/d/1gg2MSU3pUKgQLdGtp0zjJi_xvIMNFrfL/edit?usp=drive_link&ouid=115389489815414373079&rtpof=true&sd=true | R17: FALSE | S17: TOLERANSI | T17: TRUE | V17: 31/07/2026
A18: 15 | B18: SMAN 1 BOBOTSARI | C18: Kab. Purbalingga | D18: +62 852-2718-7587 (Pak Budi) | E18: 20 | F18: 50875185 | G18: SMA N 1 Bobotsari.pdf | I18: FALSE | J18: TRUE | K18: 46226 | L18: https://docs.google.com/spreadsheets/d/1ZSwBAI0EPDs-U2AEI0FXjB9aqfgMi9za0zQvUR_58LM/edit?usp=sharing | M18: 0. Masih ada 7 slot akun guru 0. Maasih ada 13 slot akun guru 1. Pemesanan 20 romel (2 jenjang) akan mendapat bonus asesmen untuk 1 jenjang lainnya, mohon untuk 1 jenjang bonus diisikan datanya pada sheet Akun Asesmen 2. Jenjang asesmen belum ada | N18: 0. akun dummy 0. akun kelas 12 0. tanggal asesmen : agustus | O18: FALSE | P18: 46181 | R18: FALSE | S18: TOLERANSI | T18: TRUE | V18: 29/07/2026
A19: 16 | B19: SMAN 1 KARANGREJA | C19: Kab. Purbalingga | D19: +62 851-7717-7227 (Mas Dita) | E19: 18 | F19: 45787500 | G19: SMA N 1 Karangreja.pdf | I19: FALSE | J19: TRUE | K19: 46226 | L19: https://docs.google.com/spreadsheets/d/1fa6DAOjXqXuA5TQKCoZe-G9mWv2imfF9gin9oilPD68/edit?usp=sharing | M19: 0. masih ada slot 15 akun guru 0. masih ada 5 slot akun siswa 0. tanggal asesmen | N19: 0. akun dummy 0. tanggal asesmen : agustus | O19: FALSE | P19: 46181 | Q19: https://docs.google.com/spreadsheets/d/1lFsDLXOFrXdZ2MlJU_FKd9KJH-HK6odP/edit?usp=drive_link&ouid=115389489815414373079&rtpof=true&sd=true | R19: FALSE | S19: TOLERANSI | T19: TRUE | V19: 29/07/2026
A20: 17 | B20: SMAN 1 KEMANGKON | C20: Kab. Purbalingga | D20: +62 852-2706-1287 (Khadiroh) | E20: 3 | F20: 7631250 | G20: SMA N 1 Kemangkon.pdf | I20: FALSE | J20: TRUE | K20: 46226 | L20: https://docs.google.com/spreadsheets/d/1p6omF5Spi2Ds1CtzgL4s23qTguKDAcE14wXHp2SfwhY/edit?usp=sharing | M20: 1. Belum ada akun admin 2. Akun free guru hanya 11, tetapi sekolah mengirimkan 42 akun 3. Email guru belum ada 5.ada 8 slot akun siswa 6. Email siswa belum ada | N20: 1. akun admin : akun email sekolah 2. terlebih 31 guru 3. email guru : email sekolah 5. dummy 6. email siswa : email sekolah | O20: FALSE | P20: 46181 | Q20: https://docs.google.com/spreadsheets/d/1C_fBykD7AcMOrMdyoUNJ9J3DYHt50scz/edit?usp=drive_link&ouid=115389489815414373079&rtpof=true&sd=true | R20: FALSE | S20: BELUM LENGKAP | T20: TRUE | V20: 46334
A21: 18 | B21: SMAN 1 Surakarta | C21: Kota Surakarta | D21: 87724037442 | E21: 3 | F21: 7631250 | G21: SMA N 1 SURAKARTA.pdf | I21: FALSE | J21: TRUE | K21: 46226 | L21: https://docs.google.com/spreadsheets/d/1m7A_2EVmGwtVmzZ07ZP-TULURVDjqYOc_7AC-slJP68/edit?gid=466295844#gid=466295844 | M21: 1. Data guru kelebihan 1 2. Data siswa kelebihan 3 | N21: TRUE | O21: FALSE | Q21: https://docs.google.com/spreadsheets/d/1W4EiHfiTJz1Bl1Aovi-5KgJFA8d1g9C3/edit?usp=drive_link&ouid=115389489815414373079&rtpof=true&sd=true | R21: FALSE | S21: LENGKAP | T21: TRUE | V21: 20/07/2026
A22: 19 | B22: SMAN 6 Surakarta | C22: Kota Surakarta | D22: 8180443393 | E22: 22 | F22: 55962315 | G22: SMA N 6 SURAKARTA.pdf | I22: FALSE | J22: TRUE | K22: 46227 | L22: https://docs.google.com/spreadsheets/d/1DmAMOHAPCZVFjXohh2npdjrheBh78yXzfwmTWh0sccI/edit?usp=sharing | M22: 0. masih ada 11 slot akun guru 0. asesmen nya jenjang apa? 0. ada beberapa siswa yang NISN nya belum ada 0. akun siswa lebih 330 | N22: 0. akun dummy 0. asesmen kelas 12 dan lebih 50 siswa, dummy 0. its ok 0. asesmen | O22: FALSE | P22: 46181 | R22: FALSE | S22: TOLERANSI | T22: TRUE | V22: 27/07/2026
A23: 20 | B23: SMAN 7 Surakarta | C23: Kota Surakarta | D23: 8122613638 | E23: 3 | F23: 7631250 | G23: SMA N 7 SURAKARTA.pdf | I23: FALSE | J23: TRUE | K23: 46227 | L23: https://docs.google.com/spreadsheets/d/1QsCEPvPwnFLgOEYfITG34vgyhe-3AUQFk0qo4qfsoiU/edit?usp=sharing | M23: 1. Belum ada spreadsheet link pengumpulan akun | N23: 1. Belum ada spreadsheet link pengumpulan akun | O23: FALSE | P23: 46181 | Q23: https://docs.google.com/spreadsheets/d/1AcRzSeolCAq26Qlk-HteCtiBfJny6Hv7/edit?usp=drive_link&ouid=115389489815414373079&rtpof=true&sd=true | R23: FALSE | S23: BELUM LENGKAP | T23: TRUE | V23: 23/07/2026
A24: 21 | B24: SMAN 5 Surakarta | C24: Kota Surakarta | D24: 83845157793 | E24: 10 | F24: 25437315 | G24: SMA N 5 SURAKARTA.pdf | I24: FALSE | J24: TRUE | K24: 46226 | L24: https://docs.google.com/spreadsheets/d/1yxt_BoSmnFEf_l2yXnAiRZSuXk62CkeUNaUMkL65Piw/edit?usp=sharing | M24: 0. masih ada 6 slot akun siswa | N24: akun dummy | O24: FALSE | P24: 46181 | Q24: https://docs.google.com/spreadsheets/d/19zzl39pHvOtPjj5Nt8xoA16aFdijXf8n/edit?usp=drive_link&ouid=115389489815414373079&rtpof=true&sd=true | R24: FALSE | S24: TOLERANSI | T24: TRUE | V24: 21/07/2026
A25: 22 | B25: SMAN 8 Surakarta | C25: Kota Surakarta | D25: 85186064433 | E25: 22 | F25: 55962315 | G25: SMA N 8 SURAKARTA.pdf | I25: FALSE | J25: TRUE | K25: 46226 | L25: https://docs.google.com/spreadsheets/d/1OGM7aTTUVoutWv8W3TZgZ9fIHb_EDidI/edit?usp=sharing&ouid=108569477961290785172&rtpof=true&sd=true | M25: 1. Akun asesmen belum ada\ 0. masih ada 14 slot akun guru 0. masih ada 18 slot akun siswa | N25: 1. asesmen = agustus 0. akun dummy | O25: FALSE | P25: 46181 | Q25: https://docs.google.com/spreadsheets/d/1MWNsv0r9kA2oOevfNZrBm3WWIDKV_BW6/edit?usp=drive_link&ouid=115389489815414373079&rtpof=true&sd=true | R25: FALSE | S25: TOLERANSI | T25: TRUE | V25: 24/07/2026
A26: 23 | B26: SMAN 4 Surakarta | C26: Kota Surakarta | D26: 081329192211 (Bu Vero) | E26: 11 | F26: 27981435 | G26: SMA N 4 SURAKARTA.pdf | I26: FALSE | J26: TRUE | K26: 46226 | L26: https://docs.google.com/spreadsheets/d/1e1oOva02EdoIh3-DUprjtAU8DUt1PTfWFdMLr7pjYJY/edit?gid=1512552771#gid=1512552771 | M26: 3. akun asesmen 0. masih ada 23 akun slot guru 0. masih ada 3 slot akun siswa | N26: 3. asesmen : agustus 0. dummy | O26: FALSE | R26: FALSE | S26: BELUM LENGKAP | T26: TRUE | V26: 22/07/2026
A27: 24 | B27: SMAN 1 Tuntang | C27: Kab Semarang | D27: +62 856-2834-712 (Bapak Yoga) | E27: 19 | F27: 48331065 | G27: SMA N 1 Tuntang.pdf | I27: FALSE | J27: TRUE | K27: 46226 | L27: https://docs.google.com/spreadsheets/d/1kAZnubvfoYU3qicPfsPKBCeidFzlaX9K/edit?usp=sharing&ouid=108569477961290785172&rtpof=true&sd=true | M27: 2. akun asesmen 0. masih ada 13 slot akun guru yang kosong 0. masih ada 45 slot akun siswa yang kosong | N27: 2. asesmen = agustus 0. dummy | O27: FALSE | P27: 46211 | Q27: https://docs.google.com/spreadsheets/d/1-VDtEqo7Z7a1iqDjUuIO4siY6d13xk3W/edit?usp=drive_link&ouid=115389489815414373079&rtpof=true&sd=true | R27: FALSE | S27: TOLERANSI | T27: TRUE | U27: 13-07-2026 | V27: 13-07-2026
A28: 25 | B28: SMAN 1 Bojong | C28: Kab. Pekalongan | D28: 85856087073 | E28: 10 | F28: 25437315 | G28: SMA N 1 Bojong.pdf | I28: FALSE | J28: TRUE | K28: 46228 | L28: https://docs.google.com/spreadsheets/d/10cNnmrliHxnOFyuxrs_teqm0nqxpkLXhvgVGp7Q52vA/edit?usp=sharing | M28: 1. Belum ada spreadsheet link pengumpulan akun | N28: 1. Belum ada spreadsheet link pengumpulan akun | O28: FALSE | P28: 46181 | Q28: https://docs.google.com/spreadsheets/d/1V-7C8r7lAApBL-0nn7EJFrcrFiGJw8eB/edit?usp=drive_link&ouid=115389489815414373079&rtpof=true&sd=true | R28: FALSE | S28: BELUM LENGKAP | T28: TRUE | V28: 46364
A29: 26 | B29: SMAN 10 Purworejo | C29: Kab. Purworejo | D29: 081328765042 (bu uwatun) | E29: 7 | F29: 17806065 | G29: SMA N 10 Purworejo.pdf | I29: FALSE | J29: TRUE | K29: 46227 | L29: https://docs.google.com/spreadsheets/d/1eKPRntp_0HX3Rk4mIe9r1cUHThTc4bLDqfPcKTDycso/edit?usp=sharing | M29: 0. masih ada 2 slot akun siswa 0. berleebih akun guru 13 0. ada beberapa akun siswa yang belum ada email dan NISN | N29: 0. dummy 0. diberikan 0. email sekolah dan toleransi | O29: FALSE | P29: 46181 | Q29: https://docs.google.com/spreadsheets/d/19Pe70FD2MH6JS4yKNZt23XiCpsKHAaD7/edit?usp=drive_link&ouid=115389489815414373079&rtpof=true&sd=true | R29: FALSE | S29: BELUM LENGKAP | T29: TRUE | V29: 29/07/2026
A30: 27 | B30: SMAN 1 Purworejo | C30: Kab. Purworejo | D30: 85878474228 | E30: 11 | F30: 27981435 | G30: SMA N 1 Purworejo.pdf | I30: FALSE | J30: TRUE | K30: 46227 | L30: https://docs.google.com/spreadsheets/d/1WiVOOx43N5a6MSvfqy0yHPMP2qQe0IQj1pmUlvkyzDc/edit?usp=sharing | M30: 1. lengkap 2. masih ada 2 slot akun siswa | N30: 0. dummy | O30: FALSE | P30: 46181 | R30: FALSE | S30: TOLERANSI | T30: TRUE | V30: 24/07/2026
A31: 28 | B31: SMAN 1 Maos | C31: Kab.Cilacap | D31: 85869707920 | E31: 3 | F31: 7631250 | G31: SMA N 1 Maos.pdf | I31: FALSE | J31: TRUE | K31: 46227 | L31: https://docs.google.com/spreadsheets/d/1wRS0R65PQKEkYL63vDmge15jBVC1QLee5ba3REkGmZA/edit?usp=sharing | M31: 1. Belum ada spreadsheet link pengumpulan akun | O31: FALSE | Q31: https://docs.google.com/spreadsheets/d/1H0oe4l35Wf1ePjwThYR2Y97qlm2SzVEW/edit?usp=drive_link&ouid=115389489815414373079&rtpof=true&sd=true | R31: FALSE | S31: BELUM LENGKAP | T31: TRUE | V31: 46150
A32: 29 | B32: SMAN 9 Surakarta | C32: Kota Surakarta | D32: 081325808089 (pak heru) | E32: 5 | F32: 12718935 | G32: SMA N 9 Surakarta.pdf | I32: FALSE | J32: TRUE | K32: 46226 | L32: https://docs.google.com/spreadsheets/d/1KArUc2J2u_QA7vPnLl1Q3kzI7dWl8PLGm6MnDcVgKh0/edit?gid=466295844#gid=466295844 | M32: masih trdpt 18 slot akun siswa | N32: 0. akun dummy | O32: FALSE | P32: 46181 | Q32: https://docs.google.com/spreadsheets/d/1n3UiHysoEHO_2Y-JWadx_NH4A_PQ50gl/edit?usp=drive_link&ouid=115389489815414373079&rtpof=true&sd=true | R32: FALSE | S32: TOLERANSI | T32: TRUE | V32: 21/07/2026
A33: 30 | B33: SMAN 2 Surakarta | C33: Kota Surakarta | D33: 082134133519 (bu tina) | E33: 5 | F33: 12718935 | G33: SMA N 2 Surakarta.pdf | I33: FALSE | J33: TRUE | K33: 46226 | L33: https://docs.google.com/spreadsheets/d/1e5sA6lyuNs8sXO6knnjW-cr-bzH4C7YpqvwE89xrgHc/edit?usp=sharing | M33: 0. masih ada 20 slot akun siswa | N33: 0. akun dummy | O33: FALSE | P33: 46211 | Q33: https://docs.google.com/spreadsheets/d/16gtsReCm4XMKCVlwbUDyDNASrKEMXS0T/edit?usp=drive_link&ouid=115389489815414373079&rtpof=true&sd=true | R33: FALSE | S33: TOLERANSI | T33: TRUE | V33: 22/07/2026
A34: 31 | B34: SMAN 1 Weleri | C34: Kab. Kendal | D34: 081905915695 (pak catur) | E34: 9 | F34: 22893750 | G34: SMA N 1 Weleri.pdf | I34: FALSE | J34: TRUE | K34: 46226 | L34: https://docs.google.com/spreadsheets/d/1l3kAQXrun0mvLUQRHPZkoG50U20B9qdiGKE82DbeV24/edit?gid=1512552771#gid=1512552771 | M34: 1. belum adan akun wakur 2. kelas yang diajar 0. masih ada 6 slot akun guru 0. akun guru berlebih harusnya 33, tetapi mengirimkan 51 | O34: FALSE | Q34: https://docs.google.com/spreadsheets/d/1V3tC6F8bOa7MVAdmleQemd4mIzb-MBun/edit?usp=drive_link&ouid=115389489815414373079&rtpof=true&sd=true | R34: FALSE | S34: BELUM LENGKAP | T34: TRUE | V34: 46120
A35: 32 | B35: SMAN 7 Semarang | C35: Kota Semarang | D35: 81390143368 | E35: 21 | F35: 53418750 | G35: https://drive.google.com/file/d/1LOs2jtuWAExgVUx75DuyHLJPoDJkpg6s/view?usp=drive_link | I35: FALSE | J35: TRUE | K35: 46229 | L35: https://docs.google.com/spreadsheets/d/1fQKBjHuICXfjvjAl5IHKUlSkMHstcnfT1_MPFXe-vHM/edit?usp=sharing | M35: 0. masih ada 22 slot akun guru 0. masih ada 5 slot akun siswa 0. tanggal pelaksanaan asesmen | N35: 0. akun dummy 0. asesmen = agustus | O35: FALSE | P35: 46181 | R35: FALSE | S35: BELUM LENGKAP | T35: TRUE | V35: 46303
A36: 33 | B36: SMAN 1 Mirit | C36: Kab. Kebumen | D36: 81393331196 | E36: 6 | F36: 15262500 | G36: https://drive.google.com/file/d/1EeX5Z6cBy_RWuVSuE-XeVEQKU9Qj0KXg/view?usp=drive_link | I36: FALSE | J36: TRUE | K36: 46227 | L36: https://docs.google.com/spreadsheets/d/1hrw1MGr-EeLV0mUbyV_TdzcdCLBAXIds65D7YGZLr5o/edit?usp=sharing | M36: 0. akun guru ada 2 slot 0. akun siswa ada 2 slot | N36: akun dummy | O36: FALSE | P36: 46181 | Q36: https://docs.google.com/spreadsheets/d/1492AxFupEhRzhOViVPHzyc-V4xmMf3U3/edit?usp=drive_link&ouid=115389489815414373079&rtpof=true&sd=true | R36: FALSE | S36: BELUM LENGKAP | T36: TRUE | V36: 28/07/2026
A37: 34 | B37: SMAN 1 Kebumen | C37: Kab. Kebumen | D37: 81328765042 | E37: 20 | F37: 50875185 | G37: SMA N 1 Kebumen.pdf | I37: FALSE | J37: TRUE | K37: 46227 | L37: https://docs.google.com/spreadsheets/d/1CNairctBlR3hZFRmDHvO7BKUeJi4Ay1saT9r_l1bjUA/edit?usp=sharing | M37: 0. masih ada 16 slot akun guru 0. masih ada 7 slot akun siswa 0. tanggal asesmen | N37: 0. akun dummy 0. tanggal asesmen = agustus | O37: FALSE | P37: 46181 | Q37: https://docs.google.com/spreadsheets/d/13Nus8tGFmXQpHRpUkzsNbI7QaCMDWstV/edit?usp=drive_link&ouid=115389489815414373079&rtpof=true&sd=true | R37: FALSE | S37: BELUM LENGKAP | T37: TRUE | V37: 46211
A38: 35 | B38: SMAN 1 Batang | C38: Kab. Batang | D38: 85868812973 | E38: 4 | F38: 10174815 | G38: https://drive.google.com/file/d/1mlaMFKYgPU6oFRlz-XbaOt-eAex0JEty/view?usp=drivesdk | I38: FALSE | J38: TRUE | K38: 46228 | L38: https://docs.google.com/spreadsheets/d/1G5IQ3AnZ8G8VW7htTgQvcj3vrGxPmsxeQd4DV_-0ztA/edit?usp=sharing | O38: FALSE | P38: 46181 | R38: FALSE | S38: TOLERANSI | T38: TRUE | V38: 46364
A39: 36 | B39: SMAN 1 Kutowinangun | C39: Kab. Kebumen | D39: 85728161982 | E39: 20 | F39: 50875185 | G39: SMA N 1 Kutowinangun.pdf | I39: FALSE | J39: TRUE | K39: 46227 | L39: https://docs.google.com/spreadsheets/d/1-ctCtAukmUpkuhY36Xc6uOVycArPOApRo_ditp3-y9U/edit?usp=sharing | M39: 0. masih ada slot 16 akun guru 0. masih ada 11 slot akun siswa 0. tanggal asesmen | N39: 0. akun dummy 0. tanggal asesmen agustus | O39: FALSE | P39: 46181 | Q39: https://docs.google.com/spreadsheets/d/1Oh_TGjKQSq83DO1UUreB2SHMHtqYYkHr/edit?usp=drive_link&ouid=115389489815414373079&rtpof=true&sd=true | R39: FALSE | S39: TOLERANSI | T39: TRUE | V39: 31/07/2026
A40: 37 | B40: SMAN 1 Bawang | C40: Kab. Banjarnegara | D40: 85227343905 | E40: 10 | F40: 25437315 | G40: SMA N 1 Bawang Banjarnegara.pdf | I40: FALSE | J40: TRUE | K40: 46227 | L40: https://docs.google.com/spreadsheets/d/1do5pCoVYWyIsBItMHfGblQ_GmkqFfRA1xllSx7Hs5h8/edit?usp=sharing | M40: 0. masih ada 5 slot akun guru 0. masih ada 11 akun siswa | N40: 0. akun dummy | O40: FALSE | P40: 46181 | Q40: https://docs.google.com/spreadsheets/d/1Upb3fl2eVo1FL6KgK6FYR8DwFtMCJEz0/edit?usp=drive_link&ouid=115389489815414373079&rtpof=true&sd=true | R40: FALSE | S40: TOLERANSI | T40: TRUE | V40: 13/08/2026
A41: 38 | B41: SMAN 2 Batang | C41: Kab. Batang | D41: 85642669512 | E41: 3 | F41: 7631250 | G41: SMA N 2 Batang.pdf | I41: FALSE | J41: TRUE | K41: 46228 | L41: https://docs.google.com/spreadsheets/d/1mqNQQFgTzkOm42WKPTk6D4KEakstqG0Fe0l2UGgrPpQ/edit?usp=sharing | M41: 1. Belum ada spreadsheet link pengumpulan akun | N41: 1. Belum ada spreadsheet link pengumpulan akun | O41: FALSE | P41: 46181 | R41: FALSE | S41: BELUM LENGKAP | T41: TRUE | V41: 46364
...

Sheet PEMBUATAN AKUN B+
A6: SEKOLAH | B6: CATATAN
A7: SMAN 1 SRAGI | B7: Siswa membuat akun sendiri melalui aktuvasi

Sheet SPJ 
A1: No | B1: KIRIM SPJ | C1: Nama Sekolah | D1: SPJ SIPLAH | E1: A2 | F1: PKS | G1: Catatan
A2: 1 | B2: 13-10-26 | C2: SMAN 1 Kajen | D2: TRUE | E2: FALSE | F2: FALSE | G2: menunggu jawaban sekolah
A3: 2 | B3: 9/28/2026 (kurang surat penawaran) | C3: SMAN 1 Ambarawa | D3: TRUE | E3: TRUE | F3: FALSE | G3: Alamat pengiriman dokumen ke: Kepala SMAN 1 Ambarawa, Jl. Yos Sudarso no. 46, Kec. Ambarawa, Kab Semarang 50612, narahubung Yohana Yuliani WA, 082138231186 selain itu, kami jg membutuhkan surat penawaran dgn nomor surat dan tanggal diatas dan MOU/PKS tertanggal 24 Agustus 2026
A4: 3 | B4: 46291 | C4: SMAN 10 Semarang | D4: TRUE | E4: FALSE | F4: FALSE | G4: Ya mbak, tolong dokumen fisik dpt dikirimkan ke sekolah. Untuk Dokumen Siplah dan lainnya bisa komunikasi dg Bendahara Ibu Farah Dina (+62 81215279547) 1. SMAN 10 Semarang (Jl. Padi Raya No.16, Gebangsari, Kecamatan Genuk, Kota Semarang, Jawa Tengah 50117) 2. SMAN 11 Semarang (Jl. Lamper Tengah XIV, RT.01/RW.01, Kelurahan Lamper Tengah, Kecamatan Semarang Selatan, Kota Semarang, Jawa Tengah 50248) Terima kasih
A5: 4 | B5: 46291 | C5: SMAN 11 Semarang | D5: TRUE | E5: FALSE | F5: FALSE | G5: Ya mbak, tolong dokumen fisik dpt dikirimkan ke sekolah. 1. SMAN 10 Semarang (Jl. Padi Raya No.16, Gebangsari, Kecamatan Genuk, Kota Semarang, Jawa Tengah 50117) 2. SMAN 11 Semarang (Jl. Lamper Tengah XIV, RT.01/RW.01, Kelurahan Lamper Tengah, Kecamatan Semarang Selatan, Kota Semarang, Jawa Tengah 50248) Terima kasih konfirm ke bendagaea
A6: 5 | B6: 13-10-26 | C6: SMAN 2 Ungaran | D6: TRUE | E6: FALSE | F6: FALSE | G6: Pagi pak untuk dokumen mohon dikirim dalam bentuk cetak/print Dapat dikirim melalui alamat Jl. Diponegoro No.277, Ngablak, Candirejo, Kec. Ungaran Bar., Kabupaten Semarang, Jawa Tengah Narahubung : Faishal - 085727449295 Termasuk nota dan kwitansi pembayaran
A7: 6 | B7: konfirm | C7: SMAN 1 Klaten | D7: FALSE | E7: FALSE | F7: FALSE | G7: belum bayar
A8: 7 | B8: belum bayar | C8: SMAN 2 Klaten | D8: TRUE | E8: FALSE | F8: FALSE | G8: belum bayar
A9: 8 | B9: 46293 | C9: SMAN 3 Klaten | D9: TRUE | E9: TRUE | F9: FALSE | G9: Untuk pengiriman dokumen bisa ke alamat berikut nggih : Nama : Ahyana Febri Eka Saputri Alamat : SMAN 3 Klaten Jl. Mayor sunaryo 42 jonggrangan Klaten utara 57435 Nomor HP : 08562580203
A10: 9 | B10: FALSE | C10: SMAN 1 Sragi | D10: FALSE | E10: FALSE | F10: FALSE | G10: belum bayar
A11: 10 | B11: FALSE | C11: SMAN 3 Surakarta | D11: FALSE | E11: FALSE | F11: FALSE | G11: belum bayar
A12: 11 | B12: 13-10-26 | C12: SMAN 1 Purwokerto | D12: TRUE | E12: FALSE | F12: FALSE | G12: SPJ scan
A13: 12 | B13: 46293 | C13: SMAN 2 Purbalingga | D13: TRUE | E13: TRUE | F13: FALSE | G13: +62 852-2737-3018
A14: 13 | B14: 46293 | C14: SMAN 1 REMBANG | D14: TRUE | E14: FALSE | F14: FALSE | G14: pengiriman ke pak sam
A15: 14 | B15: 46293 | C15: SMAN 1 KUTASARI | D15: TRUE | E15: FALSE | F15: FALSE | G15: menunggu dokumen tambahan
A16: 15 | B16: 46293 | C16: SMAN 1 BOBOTSARI | D16: TRUE | E16: FALSE | F16: FALSE | G16: menunggu jawaban sekolah
A17: 16 | B17: 46293 | C17: SMAN 1 KARANGREJA | D17: TRUE | E17: FALSE | F17: FALSE | G17: menunggu jawaban sekolah
A18: 17 | B18: FALSE | C18: SMAN 1 KEMANGKON | D18: FALSE | E18: FALSE | F18: FALSE | G18: belum bayar
A19: 18 | B19: FALSE | C19: SMAN 1 Surakarta | D19: FALSE | E19: FALSE | F19: FALSE | G19: belum bayar
A20: 19 | B20: FALSE | C20: SMAN 6 Surakarta | D20: FALSE | E20: FALSE | F20: FALSE | G20: belum bayar
A21: 20 | B21: FALSE | C21: SMAN 7 Surakarta | D21: FALSE | E21: FALSE | F21: FALSE | G21: belum bayar
A22: 21 | B22: FALSE | C22: SMAN 5 Surakarta | D22: FALSE | E22: FALSE | F22: FALSE | G22: belum bayar
A23: 22 | B23: FALSE | C23: SMAN 8 Surakarta | D23: FALSE | E23: FALSE | F23: FALSE | G23: belum bayar
A24: 23 | B24: FALSE | C24: SMAN 4 Surakarta | D24: FALSE | E24: FALSE | F24: FALSE | G24: belum bayar
A25: 24 | B25: 29/09/2026 | C25: SMAN 1 Tuntang | D25: TRUE | E25: FALSE | F25: FALSE | G25: menunggu jawaban sekolah
A26: 25 | B26: FALSE | C26: SMAN 1 Bojong | D26: FALSE | E26: FALSE | F26: FALSE | G26: belum bayar
A27: 26 | B27: 13/10/2026 | C27: SMAN 10 Purworejo | D27: TRUE | E27: TRUE | F27: FALSE | G27: menunggu jawaban sekolah
A28: 27 | B28: 13-10-26 | C28: SMAN 1 Purworejo | D28: TRUE | E28: TRUE | F28: FALSE | G28: cetak di sheet 2 kirim ke SMA NEGERI 1 PURWOREJO, JL. Tentara Pelajar No. 55 Sibung Pangenjurutengah Kec. Purworejo. Kab. Purworejo a.n Yuni Nurhayati-085878474228 Mou untuk paket kelas XI dengan rombel 11 kelas (@36 siswa) tahun anggaran 2026-2027 identitas KS nama : Cahyo Winarno, S.Pd., M.Pd. NIP. 197510221999031006
A29: 28 | B29: 13-10-26 | C29: SMAN 1 Maos | D29: TRUE | E29: TRUE | F29: FALSE | G29: belum bayar
A30: 29 | B30: 46293 | C30: SMAN 9 Surakarta | D30: TRUE | E30: FALSE | F30: FALSE | G30: +62 822-4241-0477
A31: 30 | B31: FALSE | C31: SMAN 2 Surakarta | D31: FALSE | E31: FALSE | F31: FALSE | G31: belum bayar
A32: 31 | B32: 46291 | C32: SMAN 1 Weleri | D32: TRUE | E32: TRUE | F32: FALSE | G32: Dikirim ke Sri Widarti Alamat SMAN 1 Weleri, Jln Bahari No 17, Peniten Desa Karanganom, kec. Weleri, Kab. Kendal, Jawa Tengah.
A33: 32 | B33: FALSE | C33: SMAN 7 Semarang | D33: FALSE | E33: FALSE | F33: FALSE | G33: belum bayar
A34: 33 | B34: FALSE | C34: SMAN 1 Mirit | D34: FALSE | E34: FALSE | F34: FALSE | G34: belum bayar
A35: 34 | B35: tambahan a2 | C35: SMAN 1 Kebumen | D35: FALSE | E35: FALSE | F35: FALSE | G35: belum bayar
A36: 35 | B36: 13-10-26 | C36: SMAN 1 Batang | D36: TRUE | E36: TRUE | F36: FALSE | G36: menunggu jawaban sekolah
A37: 36 | C37: SMAN 1 Kutowinangun | D37: FALSE | E37: FALSE | F37: FALSE | G37: belum bayar
A38: 37 | B38: 13-10-26 | C38: SMAN 1 Bawang | D38: TRUE | E38: FALSE | F38: FALSE | G38: +62 813-2807-5347 (catur)
A39: 38 | B39: 46032 | C39: SMAN 2 Batang | D39: TRUE | E39: FALSE | F39: FALSE | G39: menunggu jawaban sekolah
A40: 39 | B40: 13-10-26 | C40: SMAN 3 Sukoharjo | D40: TRUE | E40: FALSE | F40: FALSE | G40: menunggu jawaban sekolah
...

Sheet UPDATE AKUN
A1: Nama Sekolah | B1: Tanggal Kirim Akun | C1: Kekurangan | D1: Keterangan | E1: SPJ + Dokumen
A2: SMAN 1 Kajen | B2: 21/08/2026 | C2: lengkap
A3: SMAN 1 Ambarawa | B3: 21/08/2026 | C3: lengkap
A4: SMAN 10 Semarang | B4: 19/08/2026 | D4: konfirmasi 23 akun siswa
A5: SMAN 11 Semarang | B5: 21/08/2026
A6: SMAN 2 Ungaran | B6: 21/08/2026
A7: SMAN 1 Klaten | B7: 21/08/2026 | C7: lengkap | E7: asesmen semua belum dikirim
A8: SMAN 2 Klaten | B8: 21/08/2026 | C8: lengkap
A9: SMAN 3 Klaten | B9: 21/08/2026 | C9: lengkap
A10: SMAN 1 Sragi | B10: 21/08/2026
A11: SMAN 3 Surakarta | B11: 21/08/2026 | C11: lengkap
A12: SMAN 1 Purwokerto | B12: 21/08/2026 | C12: tanggal asesmen
A13: SMAN 2 Purbalingga | B13: 21/08/2026 | C13: tanggal asesmen | H13: 1. SMAN 1 Nguter : kurang akun asesmen. Belum lengkap tanggal asesmen nya
A14: SMAN 1 REMBANG | B14: 21/08/2026 | C14: tanggal asesmen | H14: 2. SMAN 9 Surakarta : lengkap
A15: SMAN 1 KUTASARI | B15: 21/08/2026 | C15: tanggal asesmen | H15: 3. SMAN 4 Surakarta : kurang akun asesmen. Belum lengkap data asesmen nya
A16: SMAN 1 BOBOTSARI | B16: 21/08/2026 | H16: 4. SMAN 7 Semarang : kurang akun asesmen. Belum lengkap tanggal asesmen nya
A17: SMAN 1 KARANGREJA | B17: 21/08/2026 | C17: tanggal asesmen | H17: 5. SMAN 1 Prembun : lengkap
A18: SMAN 1 KEMANGKON | B18: 21/08/2026 | C18: lengkap | H18: 6. SMAN 2 Purworejo : kurang akun asesmen. Belum lengkap data asesmen nya
A19: SMAN 1 Surakarta | B19: 21/08/2026 | C19: lengkap | H19: 7. SMAN 2 Ungaran : kurang akun asesmen. Belum lengkap tanggal asesmen nya
A20: SMAN 6 Surakarta | B20: 19/08/2026 | D20: pergantian jenjang 21/08/2026 | H20: 8. SMAN 1 Weleri : lengkap
A21: SMAN 7 Surakarta | B21: 21/08/2026 | C21: lengkap | H21: 9. SMAN 1 Maos : lengkap
A22: SMAN 5 Surakarta | B22: 21/08/2026 | C22: lengkap | H22: 10. SMAN 3 Cilacap : lengkap
A23: SMAN 8 Surakarta | B23: 21/08/2026 | C23: data asesmen | H23: 11. SMAN 1 Tawangsari : kurang akun asesmen. Belum lengkap tanggal asesmen nya
A24: SMAN 4 Surakarta | B24: 21/08/2026 | H24: 12. SMAN 2 Purbalingga : kurang akun asesmen. Belum lengkap tanggal asesmen nya
A25: SMAN 1 Tuntang | B25: 21/08/2026 | C25: data asesmen | H25: 13. SMAN 1 Klaten : lengkap
A26: SMAN 1 Bojong | B26: 21/08/2026 | C26: lengkap | H26: 14. SMAN 1 Sragi : kurang akun asesmen. data lengkap
A27: SMAN 10 Purworejo | B27: 21/08/2026 | C27: lengkap | H27: 15. SMAN 1 Kajen : lengkap
A28: SMAN 1 Purworejo | B28: 21/08/2026 | C28: lengkap | H28: 16. SMAN 1 Purwokerto : kurang akun asesmen. Belum lengkap tanggal asesmen nya
A29: SMAN 1 Maos | B29: 21/08/2026 | C29: lengkap | H29: 17. SMAN 1 Surakarta : lengkap
A30: SMAN 9 Surakarta | B30: 21/08/2026 | C30: lengkap | H30: 18. SMAN 5 Surakarta : lengkap
A31: SMAN 2 Surakarta | B31: 21/08/2026 | C31: lengkap | H31: 19. SMAN 2 Surakarta : lengkap
A32: SMAN 1 Weleri | B32: 21/08/2026 | C32: lengkap | H32: 20. SMAN 9 Surakarta : lengkap
A33: SMAN 7 Semarang | B33: 21/08/2026 | C33: tanggal asesmen | H33: 21. SMAN 8 Surakarta : kurang akun asesmen. Belum lengkap data asesmen nya
A34: SMAN 1 Mirit | B34: 21/08/2026 | C34: lengkap | H34: 22. SMAN 1 Tuntang : kurang akun asesmen. Belum lengkap data asesmen nya
A35: SMAN 1 Kebumen | B35: 21/08/2026 | C35: tanggal asesmen | H35: 23. SMAN 1 Weleri : lengkap
A36: SMAN 1 Batang | B36: 19/08/2026 | D36: proses oleh PE | H36: 24. SMAN 7 Surakarta : lengkap dengan akun kosongan
A37: SMAN 1 Kutowinangun | B37: 21/08/2026 | C37: tanggal asesmen | H37: 25. SMAN 1 Purworejo : lengkap
A38: SMAN 1 Bawang | B38: 21/08/2026 | C38: lengkap | H38: 26. SMAN 1 Kebumen : kurang akun asesmen. Belum lengkap tanggal asesmen nya
A39: SMAN 2 Batang | B39: 21/08/2026 | C39: lengkap | H39: 27. SMAN 1 Mirit : lengkap
A40: SMAN 3 Sukoharjo | B40: 21/08/2026 | C40: data asesmen | H40: 28. SMAN 1 Kutowinangun : kurang akun asesmen. Belum lengkap tanggal asesmen nya
...

Sheet Sekolah Aplikasi B+
A1: Link : | B1: https://data.kemendikdasmen.go.id/data-induk/satpen/daftar?kodeWilayah=030000&bentuk=dikmen
Q2: Daftar Nama Sekolah sudah Upload Aplikasi B+
A4: PROVINSI | B4: NPSN | C4: Nama | D4: Bentuk | E4: Jenis | F4: Status | G4: Jenjang | H4: Kabupaten | I4: Kecamatan | J4: Kelurahan | K4: Alamat | L4: Jalur | M4: Pembina | Q4: Nama Sekolah | R4: NPSN | S4: Jenjang | T4: Kota / Kab | U4: Provinsi | V4: Upload di Aplikasi | W4: Tgl Bayar | Y4: Akun B+
A5: JAWA TENGAH | B5: 20303241 | C5: SMK MUHAMMADIYAH BOBOTSARI | D5: SMK | E5: PENDIDIKAN KEJURUAN | F5: SWASTA | G5: PENDIDIKAN MENENGAH | H5: KAB. PURBALINGGA | I5: KEC. BOBOTSARI | J5: BOBOTSARI | K5: JL. RS.YOSOMIHARJO NO. 8 BOBOTSARI | L5: FORMAL | M5: KEMENTERIAN PENDIDIKAN DASAR DAN MENENGAH | Q5: SMA NEGERI 1 KAJEN | R5: 20323398 | S5: SMA | T5: KAB. PEKALONGAN | U5: JAWA TENGAH | V5: 23/09/2026 | W5: {=_xlfn.XLOOKUP(Q5,PEMBAYARAN!$G$6:$G3518,PEMBAYARAN!$R$6:$R3518,"Belum Bayar")} -> 46280.592
A6: JAWA TENGAH | B6: 20307632 | C6: SMAS MAARIF CANDIMULYO | D6: SMA | E6: PENDIDIKAN UMUM | F6: SWASTA | G6: PENDIDIKAN MENENGAH | H6: KAB. MAGELANG | I6: KEC. CANDIMULYO | J6: CANDIMULYO | K6: JL. BARISAN | L6: FORMAL | M6: KEMENTERIAN PENDIDIKAN DASAR DAN MENENGAH | Q6: SMA NEGERI 1 AMBARAWA | R6: 20320387 | S6: SMA | T6: KAB. SEMARANG | U6: JAWA TENGAH | V6: 23/09/2026 | W6: {=_xlfn.XLOOKUP(Q6,PEMBAYARAN!$G$6:$G3518,PEMBAYARAN!$R$6:$R3518,"Belum Bayar")} -> 46261.485
A7: JAWA TENGAH | B7: 20320249 | C7: SMK NEGERI 1 BAWEN | D7: SMK | E7: PENDIDIKAN KEJURUAN | F7: NEGERI | G7: PENDIDIKAN MENENGAH | H7: KAB. SEMARANG | I7: KEC. BAWEN | J7: BAWEN | K7: JL. KARTINI NO. 119 BAWEN | L7: FORMAL | M7: KEMENTERIAN PENDIDIKAN DASAR DAN MENENGAH | Q7: SMA NEGERI 1 SRAGI | R7: 20323502 | S7: SMA | T7: KAB. PEKALONGAN | U7: JAWA TENGAH | V7: 23/09/2026 | W7: {=_xlfn.XLOOKUP(Q7,PEMBAYARAN!$G$6:$G3518,PEMBAYARAN!$R$6:$R3518,"Belum Bayar")} -> Belum Bayar
A8: JAWA TENGAH | B8: 70033108 | C8: MA ZAMZAM AL HAZIM UNGARAN | D8: MA | E8: PENDIDIKAN UMUM | F8: SWASTA | G8: PENDIDIKAN MENENGAH | H8: KAB. SEMARANG | I8: KEC. UNGARAN TIMUR | J8: KALONGAN | K8: DUSUN BANDUNGAN RT 04 RW 03 | L8: FORMAL | M8: KEMENTERIAN AGAMA | Q8: SMA NEGERI 3 SURAKARTA | R8: 20327968 | S8: SMA | T8: KOTA SURAKARTA | U8: JAWA TENGAH | V8: 23/09/2026 | W8: {=_xlfn.XLOOKUP(Q8,PEMBAYARAN!$G$6:$G3518,PEMBAYARAN!$R$6:$R3518,"Belum Bayar")} -> Belum Bayar
A9: JAWA TENGAH | B9: 69769424 | C9: SMK ISLAM AL MADINA PAGUYANGAN | D9: SMK | E9: PENDIDIKAN KEJURUAN | F9: SWASTA | G9: PENDIDIKAN MENENGAH | H9: KAB. BREBES | I9: KEC. PAGUYANGAN | J9: PAGOJENGAN | K9: JL. LINGKAR BUMIAYU PAGOJENGAN | L9: FORMAL | M9: KEMENTERIAN PENDIDIKAN DASAR DAN MENENGAH | Q9: SMA NEGERI 1 PURWOKERTO | R9: 20302182 | S9: SMA | T9: KAB. BANYUMAS | U9: JAWA TENGAH | V9: 23/09/2026 | W9: {=_xlfn.XLOOKUP(Q9,PEMBAYARAN!$G$6:$G3518,PEMBAYARAN!$R$6:$R3518,"Belum Bayar")} -> 46269.591
A10: JAWA TENGAH | B10: 20331704 | C10: SMAS MA ARIF WADASLINTANG | D10: SMA | E10: PENDIDIKAN UMUM | F10: SWASTA | G10: PENDIDIKAN MENENGAH | H10: KAB. WONOSOBO | I10: KEC. WADASLINTANG | J10: WADASLINTANG | K10: JL. WADASLINTANG - PREMBUN KM. 01 | L10: FORMAL | M10: KEMENTERIAN PENDIDIKAN DASAR DAN MENENGAH | Q10: SMA NEGERI 2 PURBALINGGA | R10: 20303246 | S10: SMA | T10: KAB. PURBALINGGA | U10: JAWA TENGAH | V10: 23/09/2026 | W10: {=_xlfn.XLOOKUP(Q10,PEMBAYARAN!$G$6:$G3518,PEMBAYARAN!$R$6:$R3518,"Belum Bayar")} -> 46268.606
A11: JAWA TENGAH | B11: 20364902 | C11: SMK AL-IKHLAS PENDE BANJARHARJO | D11: SMK | E11: PENDIDIKAN KEJURUAN | F11: SWASTA | G11: PENDIDIKAN MENENGAH | H11: KAB. BREBES | I11: KEC. BANJARHARJO | J11: PENDE | K11: JL. RAYA CIKAKAK BANJARHARJO | L11: FORMAL | M11: KEMENTERIAN PENDIDIKAN DASAR DAN MENENGAH | Q11: SMA NEGERI 2 UNGARAN | R11: 20320241 | S11: SMA | T11: KAB. SEMARANG | U11: JAWA TENGAH | V11: 23/09/2026 | W11: {=_xlfn.XLOOKUP(Q11,PEMBAYARAN!$G$6:$G3518,PEMBAYARAN!$R$6:$R3518,"Belum Bayar")} -> 46274.472
A12: JAWA TENGAH | B12: 20312199 | C12: SLB - CG BINA SEJAHTERA | D12: SLB | E12: PENDIDIKAN KHUSUS | F12: SWASTA | G12: PENDIDIKAN MENENGAH | H12: KAB. KARANGANYAR | I12: KEC. GONDANGREJO | J12: SELOKATON | K12: DK. PANCURAN | L12: FORMAL | M12: KEMENTERIAN PENDIDIKAN DASAR DAN MENENGAH | Q12: SMA NEGERI 10 SEMARANG | R12: 20328878 | S12: SMA | T12: KOTA SEMARANG | U12: JAWA TENGAH | V12: 23/09/2026 | W12: {=_xlfn.XLOOKUP(Q12,PEMBAYARAN!$G$6:$G3518,PEMBAYARAN!$R$6:$R3518,"Belum Bayar")} -> 46274.472
A13: JAWA TENGAH | B13: 20362980 | C13: MAS NURUL ULUM | D13: MA | E13: PENDIDIKAN UMUM | F13: SWASTA | G13: PENDIDIKAN MENENGAH | H13: KAB. JEPARA | I13: KEC. WELAHAN | J13: WELAHAN | K13: JL. RAYA WELAHAN GOTRI KM. 1, WELAHAN, JEPARA | L13: FORMAL | M13: KEMENTERIAN AGAMA | Q13: SMA NEGERI 11 SEMARANG | R13: 20328879 | S13: SMA | T13: KOTA SEMARANG | U13: JAWA TENGAH | V13: 23/09/2026 | W13: {=_xlfn.XLOOKUP(Q13,PEMBAYARAN!$G$6:$G3518,PEMBAYARAN!$R$6:$R3518,"Belum Bayar")} -> 46282.499
A14: JAWA TENGAH | B14: 20315103 | C14: SLB NEGERI JEPON | D14: SLB | E14: PENDIDIKAN KHUSUS | F14: NEGERI | G14: PENDIDIKAN MENENGAH | H14: KAB. BLORA | I14: KEC. JEPON | J14: JEPON | K14: JALAN RAYA BLORA-CEPU KM. 7 JEPON | L14: FORMAL | M14: KEMENTERIAN PENDIDIKAN DASAR DAN MENENGAH | Q14: SMA NEGERI 1 KLATEN | R14: 20309676 | S14: SMA | T14: KAB. KLATEN | U14: JAWA TENGAH | V14: 23/09/2026 | W14: {=_xlfn.XLOOKUP(Q14,PEMBAYARAN!$G$6:$G3518,PEMBAYARAN!$R$6:$R3518,"Belum Bayar")} -> 46290.594
A15: JAWA TENGAH | B15: 20360580 | C15: SMK MUHAMMADIYAH PENCONGAN | D15: SMK | E15: PENDIDIKAN KEJURUAN | F15: SWASTA | G15: PENDIDIKAN MENENGAH | H15: KAB. PEKALONGAN | I15: KEC. WIRADESA | J15: BENER | K15: JL. A. YANI NO. 277 B WIRADESA | L15: FORMAL | M15: KEMENTERIAN PENDIDIKAN DASAR DAN MENENGAH | Q15: SMA NEGERI 2 KLATEN | R15: 20309689 | S15: SMA | T15: KAB. KLATEN | U15: JAWA TENGAH | V15: 23/09/2026 | W15: {=_xlfn.XLOOKUP(Q15,PEMBAYARAN!$G$6:$G3518,PEMBAYARAN!$R$6:$R3518,"Belum Bayar")}
A16: JAWA TENGAH | B16: 72367249 | C16: SMA MEGA ISLAMIC BOARDING SCHOOL | D16: SMA | E16: PENDIDIKAN UMUM | F16: SWASTA | G16: PENDIDIKAN MENENGAH | H16: KOTA SEMARANG | I16: KEC. GUNUNG PATI | J16: MANGUNSARI | K16: JL. MR. WURYANTO NO. 88 PAGER SALAM | L16: FORMAL | M16: KEMENTERIAN PENDIDIKAN DASAR DAN MENENGAH | Q16: SMA NEGERI 3 KLATEN | R16: 20309690 | S16: SMA | T16: KAB. KLATEN | U16: JAWA TENGAH | V16: 23/09/2026 | W16: {=_xlfn.XLOOKUP(Q16,PEMBAYARAN!$G$6:$G3518,PEMBAYARAN!$R$6:$R3518,"Belum Bayar")} -> 46265.489
A17: JAWA TENGAH | B17: 20362832 | C17: MA AT-TAQWA NUSAWUNGU | D17: MA | E17: PENDIDIKAN UMUM | F17: SWASTA | G17: PENDIDIKAN MENENGAH | H17: KAB. CILACAP | I17: KEC. NUSAWUNGU | J17: DANASRI LOR | K17: JL. PRAMUKA NO. 460 | L17: FORMAL | M17: KEMENTERIAN AGAMA | Q17: SMA NEGERI 1 REMBANG | R17: 20303248 | S17: SMA | T17: KAB. PURBALINGGA | U17: JAWA TENGAH | V17: 23/09/2026 | W17: {=_xlfn.XLOOKUP(Q17,PEMBAYARAN!$G$6:$G3518,PEMBAYARAN!$R$6:$R3518,"Belum Bayar")} -> 46267.483
A18: JAWA TENGAH | B18: 20321831 | C18: SMA NEGERI 1 GEMUH | D18: SMA | E18: PENDIDIKAN UMUM | F18: NEGERI | G18: PENDIDIKAN MENENGAH | H18: KAB. KENDAL | I18: KEC. GEMUH | J18: PAMRIYAN | K18: JL. NAPAK TILAS PAMRIYAN GEMUH | L18: FORMAL | M18: KEMENTERIAN PENDIDIKAN DASAR DAN MENENGAH | Q18: SMA NEGERI 1 KEMANGKON | R18: 20303238 | S18: SMA | T18: KAB. PURBALINGGA | U18: JAWA TENGAH | V18: 23/09/2026 | W18: {=_xlfn.XLOOKUP(Q18,PEMBAYARAN!$G$6:$G3518,PEMBAYARAN!$R$6:$R3518,"Belum Bayar")} -> Belum Bayar
A19: JAWA TENGAH | B19: 20311327 | C19: SMK MUHAMMADIYAH 2 WURYANTORO | D19: SMK | E19: PENDIDIKAN KEJURUAN | F19: SWASTA | G19: PENDIDIKAN MENENGAH | H19: KAB. WONOGIRI | I19: KEC. WURYANTORO | J19: WURYANTORO | K19: JL. MELATI 5 | L19: FORMAL | M19: KEMENTERIAN PENDIDIKAN DASAR DAN MENENGAH | Q19: SMA NEGERI 1 KUTASARI | R19: 20303239 | S19: SMA | T19: KAB. PURBALINGGA | U19: JAWA TENGAH | V19: 23/09/2026 | W19: {=_xlfn.XLOOKUP(Q19,PEMBAYARAN!$G$6:$G3518,PEMBAYARAN!$R$6:$R3518,"Belum Bayar")} -> 46262.619
A20: JAWA TENGAH | B20: 20330038 | C20: SMK MUHAMMADIYAH RANDUBLATUNG | D20: SMK | E20: PENDIDIKAN KEJURUAN | F20: SWASTA | G20: PENDIDIKAN MENENGAH | H20: KAB. BLORA | I20: KEC. RANDUBLATUNG | J20: PILANG | K20: JLN. DIPONEGORO NO.13 RANDUBLATUNG | L20: FORMAL | M20: KEMENTERIAN PENDIDIKAN DASAR DAN MENENGAH | Q20: SMA NEGERI 1 BOBOTSARI | R20: 20303231 | S20: SMA | T20: KAB. PURBALINGGA | U20: JAWA TENGAH | V20: 23/09/2026 | W20: {=_xlfn.XLOOKUP(Q20,PEMBAYARAN!$G$6:$G3518,PEMBAYARAN!$R$6:$R3518,"Belum Bayar")} -> 46280.592
A21: JAWA TENGAH | B21: 69888671 | C21: SMK MIFTAHUL HUDA | D21: SMK | E21: PENDIDIKAN KEJURUAN | F21: SWASTA | G21: PENDIDIKAN MENENGAH | H21: KAB. DEMAK | I21: KEC. MIJEN | J21: JLEPER | K21: JALAN RAYA MIJEN JLEPER KM 3 MIJEN DEMAK | L21: FORMAL | M21: KEMENTERIAN PENDIDIKAN DASAR DAN MENENGAH | Q21: SMA NEGERI 1 KARANGREJA | R21: 20303229 | S21: SMA | T21: KAB. PURBALINGGA | U21: JAWA TENGAH | V21: 23/09/2026 | W21: {=_xlfn.XLOOKUP(Q21,PEMBAYARAN!$G$6:$G3518,PEMBAYARAN!$R$6:$R3518,"Belum Bayar")} -> 46280.476
A22: JAWA TENGAH | B22: 79305373 | C22: SMA AL ABIDIN BILINGUAL BOARDING SCHOOL (ABBS) KARANGANYAR | D22: SMA | E22: PENDIDIKAN UMUM | F22: SWASTA | G22: PENDIDIKAN MENENGAH | H22: KAB. KARANGANYAR | I22: KEC. KARANGANYAR | J22: LALUNG | K22: JL. SADEWA - MANGGEH ANYAR | L22: FORMAL | M22: KEMENTERIAN PENDIDIKAN DASAR DAN MENENGAH | Q22: SMA NEGERI 4 SURAKARTA | R22: 20327969 | S22: SMA | T22: KOTA SURAKARTA | U22: JAWA TENGAH | V22: 23/09/2026 | W22: {=_xlfn.XLOOKUP(Q22,PEMBAYARAN!$G$6:$G3518,PEMBAYARAN!$R$6:$R3518,"Belum Bayar")} -> Belum Bayar | Y22: TRUE
A23: JAWA TENGAH | B23: 20362310 | C23: SMK KRIDA DOPLANG | D23: SMK | E23: PENDIDIKAN KEJURUAN | F23: SWASTA | G23: PENDIDIKAN MENENGAH | H23: KAB. BLORA | I23: KEC. JATI | J23: DOPLANG | K23: JLN.SUMUR UMUM DUKUHAN- DOPLANG | L23: FORMAL | M23: KEMENTERIAN PENDIDIKAN DASAR DAN MENENGAH | Q23: SMA NEGERI 5 SURAKARTA | R23: 20327970 | S23: SMA | T23: KOTA SURAKARTA | U23: JAWA TENGAH | V23: 23/09/2026 | W23: {=_xlfn.XLOOKUP(Q23,PEMBAYARAN!$G$6:$G3518,PEMBAYARAN!$R$6:$R3518,"Belum Bayar")} -> Belum Bayar | Y23: FALSE
A24: JAWA TENGAH | B24: 20340717 | C24: SMK BHAKTI KARYA SIMO | D24: SMK | E24: PENDIDIKAN KEJURUAN | F24: SWASTA | G24: PENDIDIKAN MENENGAH | H24: KAB. BOYOLALI | I24: KEC. SIMO | J24: PELEM | K24: JALAN SINGOPRONO RAYA | L24: FORMAL | M24: KEMENTERIAN PENDIDIKAN DASAR DAN MENENGAH | Q24: SMA NEGERI 6 SURAKARTA | R24: 20327971 | S24: SMA | T24: KOTA SURAKARTA | U24: JAWA TENGAH | V24: 23/09/2026 | W24: {=_xlfn.XLOOKUP(Q24,PEMBAYARAN!$G$6:$G3518,PEMBAYARAN!$R$6:$R3518,"Belum Bayar")} -> Belum Bayar | Y24: TRUE
A25: JAWA TENGAH | B25: 20362281 | C25: SMK ROBBANI KARANGTENGAH | D25: SMK | E25: PENDIDIKAN KEJURUAN | F25: SWASTA | G25: PENDIDIKAN MENENGAH | H25: KAB. DEMAK | I25: KEC. KARANG TENGAH | J25: DUKUN | K25: JL. DESA DUKUN RT 04/ RW 03, KARANGTENGAH | L25: FORMAL | M25: KEMENTERIAN PENDIDIKAN DASAR DAN MENENGAH | Q25: SMA NEGERI 8 SURAKARTA | R25: 20327973 | S25: SMA | T25: KOTA SURAKARTA | U25: JAWA TENGAH | V25: 23/09/2026 | W25: {=_xlfn.XLOOKUP(Q25,PEMBAYARAN!$G$6:$G3518,PEMBAYARAN!$R$6:$R3518,"Belum Bayar")} -> Belum Bayar | Y25: TRUE
A26: JAWA TENGAH | B26: 20330452 | C26: SMK MARDIKENYA PURWOKERTO | D26: SMK | E26: PENDIDIKAN KEJURUAN | F26: SWASTA | G26: PENDIDIKAN MENENGAH | H26: KAB. BANYUMAS | I26: KEC. PURWOKERTO TIMUR | J26: KRANJI | K26: JL. MARDIKENYA 4-6 PURWOKERTO | L26: FORMAL | M26: KEMENTERIAN PENDIDIKAN DASAR DAN MENENGAH | Q26: SMA NEGERI 7 SURAKARTA | R26: 20327972 | S26: SMA | T26: KOTA SURAKARTA | U26: JAWA TENGAH | V26: 23/09/2026 | W26: {=_xlfn.XLOOKUP(Q26,PEMBAYARAN!$G$6:$G3518,PEMBAYARAN!$R$6:$R3518,"Belum Bayar")} -> Belum Bayar
A27: JAWA TENGAH | B27: 70049208 | C27: SMK AS - SYARIF | D27: SMK | E27: PENDIDIKAN KEJURUAN | F27: SWASTA | G27: PENDIDIKAN MENENGAH | H27: KAB. GROBOGAN | I27: KEC. TOROH | J27: SUGIHAN | K27: DESA SUGIHAN, KECAMATAN TOROH, KABUPATEN GROBOGAN | L27: FORMAL | M27: KEMENTERIAN PENDIDIKAN DASAR DAN MENENGAH | Q27: SMA NEGERI 1 SURAKARTA | R27: 20327966 | S27: SMA | T27: KOTA SURAKARTA | U27: JAWA TENGAH | V27: 23/09/2026 | W27: {=_xlfn.XLOOKUP(Q27,PEMBAYARAN!$G$6:$G3518,PEMBAYARAN!$R$6:$R3518,"Belum Bayar")} -> Belum Bayar
A28: JAWA TENGAH | B28: 20325275 | C28: SMK NU 1 ADIWERNA | D28: SMK | E28: PENDIDIKAN KEJURUAN | F28: SWASTA | G28: PENDIDIKAN MENENGAH | H28: KAB. TEGAL | I28: KEC. ADIWERNA | J28: TEMBOK BANJARAN | K28: JL. RAYA BANJARAN SELATAN NO. 47 RT 20 RW 04 TEMBOK BANJARAN ADIWERNA KAB. TEGAL | L28: FORMAL | M28: KEMENTERIAN PENDIDIKAN DASAR DAN MENENGAH | Q28: SMA NEGERI 1 BOJONG | R28: 20338918 | S28: SMA | T28: KAB. PEKALONGAN | U28: JAWA TENGAH | V28: 23/09/2026 | W28: {=_xlfn.XLOOKUP(Q28,PEMBAYARAN!$G$6:$G3518,PEMBAYARAN!$R$6:$R3518,"Belum Bayar")} -> Belum Bayar
A29: JAWA TENGAH | B29: 20321837 | C29: SMA NEGERI 1 ROWOSARI | D29: SMA | E29: PENDIDIKAN UMUM | F29: NEGERI | G29: PENDIDIKAN MENENGAH | H29: KAB. KENDAL | I29: KEC. ROWOSARI | J29: TAMBAKSARI | K29: JL. BAHARI KM.5 ROWOSARI | L29: FORMAL | M29: KEMENTERIAN PENDIDIKAN DASAR DAN MENENGAH | Q29: SMA NEGERI 1 MAOS | R29: 20300731 | S29: SMA | T29: KAB. CILACAP | U29: JAWA TENGAH | V29: 23/09/2026 | W29: {=_xlfn.XLOOKUP(Q29,PEMBAYARAN!$G$6:$G3518,PEMBAYARAN!$R$6:$R3518,"Belum Bayar")} -> 46290.525
A30: JAWA TENGAH | B30: 69955740 | C30: MA MA`ARIF NU PAGUYANGAN | D30: MA | E30: PENDIDIKAN UMUM | F30: SWASTA | G30: PENDIDIKAN MENENGAH | H30: KAB. BREBES | I30: KEC. PAGUYANGAN | J30: PAGUYANGAN | K30: JALAN KEDUNGBANTENG-KEDUNGOLENG PAGUYANGAN | L30: FORMAL | M30: KEMENTERIAN AGAMA | Q30: SMA NEGERI 1 TUNTANG | R30: 20320243 | S30: SMA | T30: KAB. SEMARANG | U30: JAWA TENGAH | V30: 23/09/2026 | W30: {=_xlfn.XLOOKUP(Q30,PEMBAYARAN!$G$6:$G3518,PEMBAYARAN!$R$6:$R3518,"Belum Bayar")} -> 46273.47
A31: JAWA TENGAH | B31: 20362057 | C31: SMK BAGIMU NEGERIKU | D31: SMK | E31: PENDIDIKAN KEJURUAN | F31: SWASTA | G31: PENDIDIKAN MENENGAH | H31: KOTA SEMARANG | I31: KEC. NGALIYAN | J31: PODOREJO | K31: JL. PALIR RAYA NO. 66 - 68 | L31: FORMAL | M31: KEMENTERIAN PENDIDIKAN DASAR DAN MENENGAH | Q31: SMA NEGERI 10 PURWOREJO | R31: 20306190 | S31: SMA | T31: KAB. PURWOREJO | U31: JAWA TENGAH | V31: 23/09/2026 | W31: {=_xlfn.XLOOKUP(Q31,PEMBAYARAN!$G$6:$G3518,PEMBAYARAN!$R$6:$R3518,"Belum Bayar")} -> 46269.591
A32: JAWA TENGAH | B32: 20306867 | C32: SMA NEGERI 1 KERTEK | D32: SMA | E32: PENDIDIKAN UMUM | F32: NEGERI | G32: PENDIDIKAN MENENGAH | H32: KAB. WONOSOBO | I32: KEC. KERTEK | J32: BOJASARI | K32: JL. GATOT SUBROTO KM. 06 WONOSOBO 56371 | L32: FORMAL | M32: KEMENTERIAN PENDIDIKAN DASAR DAN MENENGAH | Q32: SMA NEGERI 1 PURWOREJO | R32: 20306202 | S32: SMA | T32: KAB. PURWOREJO | U32: JAWA TENGAH | V32: 23/09/2026 | W32: {=_xlfn.XLOOKUP(Q32,PEMBAYARAN!$G$6:$G3518,PEMBAYARAN!$R$6:$R3518,"Belum Bayar")} -> 46262.619
A33: JAWA TENGAH | B33: 69829549 | C33: SMA SYUBBANUL WATHON | D33: SMA | E33: PENDIDIKAN UMUM | F33: SWASTA | G33: PENDIDIKAN MENENGAH | H33: KAB. MAGELANG | I33: KEC. TEGALREJO | J33: DLIMAS | K33: JL. PIRIKAN GRABAG KM 2, GIRIKULON, KEC. SECANG, KAB. MAGELANG | L33: FORMAL | M33: KEMENTERIAN PENDIDIKAN DASAR DAN MENENGAH | Q33: SMA NEGERI 7 SEMARANG | R33: 20328891 | S33: SMA | T33: KOTA SEMARANG | U33: JAWA TENGAH | V33: 23/09/2026 | W33: {=_xlfn.XLOOKUP(Q33,PEMBAYARAN!$G$6:$G3518,PEMBAYARAN!$R$6:$R3518,"Belum Bayar")} -> Belum Bayar
A34: JAWA TENGAH | B34: 20363209 | C34: MAN 2 SEMARANG | D34: MA | E34: PENDIDIKAN UMUM | F34: NEGERI | G34: PENDIDIKAN MENENGAH | H34: KAB. SEMARANG | I34: KEC. TENGARAN | J34: TENGARAN | K34: JL. KELURAHAN DESA TENGARAN KEC. TENGARAN | L34: FORMAL | M34: KEMENTERIAN AGAMA | Q34: SMA NEGERI 1 MIRIT | R34: 20330283 | S34: SMA | T34: KAB. KEBUMEN | U34: JAWA TENGAH | V34: 23/09/2026 | W34: {=_xlfn.XLOOKUP(Q34,PEMBAYARAN!$G$6:$G3518,PEMBAYARAN!$R$6:$R3518,"Belum Bayar")} -> Belum Bayar
A35: JAWA TENGAH | B35: 69728555 | C35: SMK MULYA HUSADA PURWOKERTO | D35: SMK | E35: PENDIDIKAN KEJURUAN | F35: SWASTA | G35: PENDIDIKAN MENENGAH | H35: KAB. BANYUMAS | I35: KEC. SUMBANG | J35: KARANGCEGAK | K35: JL. BATURRADEN TIMUR NO.57 KARANGCEGAK SUMBANG 53183 | L35: FORMAL | M35: KEMENTERIAN PENDIDIKAN DASAR DAN MENENGAH | Q35: SMA NEGERI 1 KUTOWINANGUN | R35: 20305013 | S35: SMA | T35: KAB. KEBUMEN | U35: JAWA TENGAH | V35: 23/09/2026 | W35: {=_xlfn.XLOOKUP(Q35,PEMBAYARAN!$G$6:$G3518,PEMBAYARAN!$R$6:$R3518,"Belum Bayar")} -> Belum Bayar
A36: JAWA TENGAH | B36: 20303949 | C36: SMK COKROAMINOTO 2 BANJARNEGARA | D36: SMK | E36: PENDIDIKAN KEJURUAN | F36: SWASTA | G36: PENDIDIKAN MENENGAH | H36: KAB. BANJARNEGARA | I36: KEC. BANJARNEGARA | J36: WANGON | K36: JL. LET. JEND. SOEPRAPTO 221 | L36: FORMAL | M36: KEMENTERIAN PENDIDIKAN DASAR DAN MENENGAH | Q36: SMA NEGERI 1 WELERI | R36: 20321834 | S36: SMA | T36: KAB. KENDAL | U36: JAWA TENGAH | V36: 23/09/2026 | W36: {=_xlfn.XLOOKUP(Q36,PEMBAYARAN!$G$6:$G3518,PEMBAYARAN!$R$6:$R3518,"Belum Bayar")} -> 46255.456
A37: JAWA TENGAH | B37: 69874020 | C37: SMK TERPADU AL MINHAJ BANDAR | D37: SMK | E37: PENDIDIKAN KEJURUAN | F37: SWASTA | G37: PENDIDIKAN MENENGAH | H37: KAB. BATANG | I37: KEC. BANDAR | J37: WONOSEGORO | K37: JL. BANDAR - TULIS KM 5, WONOSEGORO 51254 | L37: FORMAL | M37: KEMENTERIAN PENDIDIKAN DASAR DAN MENENGAH | Q37: SMA NEGERI 1 BATANG | R37: 20322744 | S37: SMA | T37: KAB. BATANG | U37: JAWA TENGAH | V37: 23/09/2026 | W37: {=_xlfn.XLOOKUP(Q37,PEMBAYARAN!$G$6:$G3518,PEMBAYARAN!$R$6:$R3518,"Belum Bayar")} -> 46279.475
A38: JAWA TENGAH | B38: 20339002 | C38: SMA BOPKRI 3 PATI | D38: SMA | E38: PENDIDIKAN UMUM | F38: SWASTA | G38: PENDIDIKAN MENENGAH | H38: KAB. PATI | I38: KEC. DUKUHSETI | J38: TEGALOMBO | K38: JL. TAYU - PUNCEL KM. 15 | L38: FORMAL | M38: KEMENTERIAN PENDIDIKAN DASAR DAN MENENGAH | Q38: SMA NEGERI 2 BATANG | R38: 20322740 | S38: SMA | T38: KAB. BATANG | U38: JAWA TENGAH | V38: 23/09/2026 | W38: {=_xlfn.XLOOKUP(Q38,PEMBAYARAN!$G$6:$G3518,PEMBAYARAN!$R$6:$R3518,"Belum Bayar")} -> 46283.583
A39: JAWA TENGAH | B39: 20341018 | C39: SMK PELITA HARAPAN | D39: SMK | E39: PENDIDIKAN KEJURUAN | F39: SWASTA | G39: PENDIDIKAN MENENGAH | H39: KAB. KENDAL | I39: KEC. KANGKUNG | J39: KARANGMALANG WETAN | K39: KOMPLEK PON-PES SALAFIYAH KARANGMALANG KANGKUNG KENDAL | L39: FORMAL | M39: KEMENTERIAN PENDIDIKAN DASAR DAN MENENGAH | Q39: SMA NEGERI 1 KEBUMEN | R39: 20305010 | S39: SMA | T39: KAB. KEBUMEN | U39: JAWA TENGAH | V39: 23/09/2026 | W39: {=_xlfn.XLOOKUP(Q39,PEMBAYARAN!$G$6:$G3518,PEMBAYARAN!$R$6:$R3518,"Belum Bayar")} -> 46290.594
A40: JAWA TENGAH | B40: 69880579 | C40: SMK ISLAM SALAKBROJO | D40: SMK | E40: PENDIDIKAN KEJURUAN | F40: SWASTA | G40: PENDIDIKAN MENENGAH | H40: KAB. PEKALONGAN | I40: KEC. KEDUNGWUNI | J40: SALAKBROJO | K40: JL. RAYA MIYANGGONG RT. 01 RW. 02 | L40: FORMAL | M40: KEMENTERIAN PENDIDIKAN DASAR DAN MENENGAH | Q40: SMA NEGERI 1 BAWANG | R40: 20303985 | S40: SMA | T40: KAB. BANJARNEGARA | U40: JAWA TENGAH | V40: 23/09/2026 | W40: {=_xlfn.XLOOKUP(Q40,PEMBAYARAN!$G$6:$G3518,PEMBAYARAN!$R$6:$R3518,"Belum Bayar")} -> 46252.578
A41: JAWA TENGAH | B41: 20364930 | C41: MA NU 01 BANYUPUTIH | D41: MA | E41: PENDIDIKAN UMUM | F41: SWASTA | G41: PENDIDIKAN MENENGAH | H41: KAB. BATANG | I41: KEC. BANYUPUTIH | J41: BANYUPUTIH | K41: JL. LAPANGAN 9A | L41: FORMAL | M41: KEMENTERIAN AGAMA | Q41: SMA NEGERI 1 SUKOHARJO | R41: 20310417 | S41: SMA | T41: KAB. SUKOHARJO | U41: JAWA TENGAH | V41: 23/09/2026 | W41: {=_xlfn.XLOOKUP(Q41,PEMBAYARAN!$G$6:$G3518,PEMBAYARAN!$R$6:$R3518,"Belum Bayar")} -> Belum Bayar
...

Sheet PEMBAYARAN
D1: DAFTAR ORDER SIPLah
A2: SMAN 1 Kajen | F2: Data Otomatis dari | G2: https://docs.google.com/spreadsheets/d/1r7Tu4i1wdGSE1v7PLLbL4LHgrkp8S3KHqOdmaCZaZpc/edit?usp=sharing
A3: SMAN 1 Ambarawa | H3: TOTAL | J3: =SUBTOTAL(9,J6:J1700) -> 1600103630 | K3: =SUBTOTAL(9,K6:K1700) -> 1498353815 | L3: =SUBTOTAL(9,L6:L1700) -> 158568840 | M3: =SUBTOTAL(9,M6:M1700) -> 7207655 | N3: =SUBTOTAL(9,N6:N1700) -> 503500 | O3: =SUBTOTAL(9,O6:O1700) -> 1342615466 | W3: =SUBTOTAL(9,W6:W1700) -> 1466665500
A5: SMAN 10 Semarang | C5: NPSN | D5: No | E5: Tanggal | F5: Nomor Pesanan | G5: Nama Sekolah | H5: Kota Tujuan | I5: Jumlah | J5: Nilai Pesanan | K5: Jumlah Dibayarkan | L5: PPN | M5: PPH 22 | N5: Biaya Admin | O5: Uang yang diterima Penyedia | P5: Pembayar Pajak | Q5: Status | R5: Tanggal Penerusan Dana | S5: Nomor Invoice | T5: PO | U5: NO. PEMB | W5: NILAI PESAN ACCURATE
A6: SMAN 11 Semarang | C6: {=_xlfn.XLOOKUP(G6,'Sekolah Aplikasi B+'!$Q$5:$Q1700,'Sekolah Aplikasi B+'!$R$5:$R1700,"BELUM UPLOAD")} -> 20300719 | D6: =IFERROR(__xludf.DUMMYFUNCTION("IMPORTRANGE(""https://docs.google.com/spreadsheets/d/1r7Tu4i1wdGSE1v7PLLbL4LHgrkp8S3KHqOdmaCZaZpc/edit?usp=sharing"",""DATA SIPLAH 26!A5:T"")"),1.0) -> 1 | E6: =IFERROR(__xludf.DUMMYFUNCTION("""COMPUTED_VALUE"""),46247.0) -> 46247 | F6: =IFERROR(__xludf.DUMMYFUNCTION("""COMPUTED_VALUE"""),"PO6A7B156722B7E") -> PO6A7B156722B7E | G6: =IFERROR(__xludf.DUMMYFUNCTION("""COMPUTED_VALUE"""),"SMA NEGERI 1 KROYA") -> SMA NEGERI 1 KROYA | H6: =IFERROR(__xludf.DUMMYFUNCTION("""COMPUTED_VALUE"""),"Kab. Cilacap, Prov. Jawa Tengah") -> Kab. Cilacap, Prov. Jawa Tengah | I6: =IFERROR(__xludf.DUMMYFUNCTION("""COMPUTED_VALUE"""),1.0) -> 1 | J6: =IFERROR(__xludf.DUMMYFUNCTION("""COMPUTED_VALUE"""),7631250.0) -> 7631250 | K6: =IFERROR(__xludf.DUMMYFUNCTION("""COMPUTED_VALUE"""),7631250.0) -> 7631250 | L6: =IFERROR(__xludf.DUMMYFUNCTION("""COMPUTED_VALUE"""),756250.0) -> 756250 | M6: =IFERROR(__xludf.DUMMYFUNCTION("""COMPUTED_VALUE"""),34375.0) -> 34375 | N6: =IFERROR(__xludf.DUMMYFUNCTION("""COMPUTED_VALUE"""),10000.0) -> 10000 | O6: =IFERROR(__xludf.DUMMYFUNCTION("""COMPUTED_VALUE"""),6830625.0) -> 6830625 | P6: =IFERROR(__xludf.DUMMYFUNCTION("""COMPUTED_VALUE"""),"Toko Ladang") -> Toko Ladang | Q6: =IFERROR(__xludf.DUMMYFUNCTION("""COMPUTED_VALUE"""),"Pembayaran Diteruskan") -> Pembayaran Diteruskan | R6: =IFERROR(__xludf.DUMMYFUNCTION("""COMPUTED_VALUE"""),46248.46005787037) -> 46248.46 | S6: =IFERROR(__xludf.DUMMYFUNCTION("""COMPUTED_VALUE"""),"11220146/INV/PO6A7B156722B7E") -> 11220146/INV/PO6A7B156722B7E | T6: =IFERROR(__xludf.DUMMYFUNCTION("""COMPUTED_VALUE"""),"PE-CLCP-07") -> PE-CLCP-07 | U6: =IFERROR(__xludf.DUMMYFUNCTION("""COMPUTED_VALUE"""),"11010202.2026.08.00002") -> 11010202.2026.08.00002 | W6: =IFERROR(__xludf.DUMMYFUNCTION("""COMPUTED_VALUE"""),6875000.0) -> 6875000 | X6: =LEFT(H6,(LEN(H6)-19)) -> Kab. Cilacap
A7: SMAN 2 Ungaran | C7: {=_xlfn.XLOOKUP(G7,'Sekolah Aplikasi B+'!$Q$5:$Q1700,'Sekolah Aplikasi B+'!$R$5:$R1700,"BELUM UPLOAD")} -> 20303985 | D7: =IFERROR(__xludf.DUMMYFUNCTION("""COMPUTED_VALUE"""),2.0) -> 2 | E7: =IFERROR(__xludf.DUMMYFUNCTION("""COMPUTED_VALUE"""),46247.0) -> 46247 | F7: =IFERROR(__xludf.DUMMYFUNCTION("""COMPUTED_VALUE"""),"PO6A7D34F7CC471") -> PO6A7D34F7CC471 | G7: =IFERROR(__xludf.DUMMYFUNCTION("""COMPUTED_VALUE"""),"SMA NEGERI 1 BAWANG") -> SMA NEGERI 1 BAWANG | H7: =IFERROR(__xludf.DUMMYFUNCTION("""COMPUTED_VALUE"""),"Kab. Banjarnegara, Prov. Jawa Tengah") -> Kab. Banjarnegara, Prov. Jawa Tengah | I7: =IFERROR(__xludf.DUMMYFUNCTION("""COMPUTED_VALUE"""),1.0) -> 1 | J7: =IFERROR(__xludf.DUMMYFUNCTION("""COMPUTED_VALUE"""),2.25E7) -> 22500000 | K7: =IFERROR(__xludf.DUMMYFUNCTION("""COMPUTED_VALUE"""),2.25E7) -> 22500000 | L7: =IFERROR(__xludf.DUMMYFUNCTION("""COMPUTED_VALUE"""),2229730.0) -> 2229730 | M7: =IFERROR(__xludf.DUMMYFUNCTION("""COMPUTED_VALUE"""),101351.0) -> 101351 | N7: =IFERROR(__xludf.DUMMYFUNCTION("""COMPUTED_VALUE"""),10000.0) -> 10000 | O7: =IFERROR(__xludf.DUMMYFUNCTION("""COMPUTED_VALUE"""),2.0158919E7) -> 20158919 | P7: =IFERROR(__xludf.DUMMYFUNCTION("""COMPUTED_VALUE"""),"Toko Ladang") -> Toko Ladang | Q7: =IFERROR(__xludf.DUMMYFUNCTION("""COMPUTED_VALUE"""),"Pembayaran Diteruskan") -> Pembayaran Diteruskan | R7: =IFERROR(__xludf.DUMMYFUNCTION("""COMPUTED_VALUE"""),46252.57753472222) -> 46252.578 | S7: =IFERROR(__xludf.DUMMYFUNCTION("""COMPUTED_VALUE"""),"11270737/INV/PO6A7D34F7CC471") -> 11270737/INV/PO6A7D34F7CC471 | T7: =IFERROR(__xludf.DUMMYFUNCTION("""COMPUTED_VALUE"""),"PE-BJR-01") -> PE-BJR-01 | U7: =IFERROR(__xludf.DUMMYFUNCTION("""COMPUTED_VALUE"""),"11010202.2026.08.00003") -> 11010202.2026.08.00003 | W7: =IFERROR(__xludf.DUMMYFUNCTION("""COMPUTED_VALUE"""),2.97915E7) -> 29791500 | X7: =LEFT(H7,(LEN(H7)-19)) -> Kab. Banjarnegara
A8: SMAN 1 Klaten | C8: {=_xlfn.XLOOKUP(G8,'Sekolah Aplikasi B+'!$Q$5:$Q1700,'Sekolah Aplikasi B+'!$R$5:$R1700,"BELUM UPLOAD")} -> 20302174 | D8: =IFERROR(__xludf.DUMMYFUNCTION("""COMPUTED_VALUE"""),3.0) -> 3 | E8: =IFERROR(__xludf.DUMMYFUNCTION("""COMPUTED_VALUE"""),46247.0) -> 46247 | F8: =IFERROR(__xludf.DUMMYFUNCTION("""COMPUTED_VALUE"""),"PO6A7D702722CC2") -> PO6A7D702722CC2 | G8: =IFERROR(__xludf.DUMMYFUNCTION("""COMPUTED_VALUE"""),"SMA NEGERI 1 RAWALO") -> SMA NEGERI 1 RAWALO | H8: =IFERROR(__xludf.DUMMYFUNCTION("""COMPUTED_VALUE"""),"Kab. Banyumas, Prov. Jawa Tengah") -> Kab. Banyumas, Prov. Jawa Tengah | I8: =IFERROR(__xludf.DUMMYFUNCTION("""COMPUTED_VALUE"""),16.0) -> 16 | J8: =IFERROR(__xludf.DUMMYFUNCTION("""COMPUTED_VALUE"""),4.08E7) -> 40800000 | K8: =IFERROR(__xludf.DUMMYFUNCTION("""COMPUTED_VALUE"""),4.08E7) -> 40800000 | L8: =IFERROR(__xludf.DUMMYFUNCTION("""COMPUTED_VALUE"""),4043248.0) -> 4043248 | M8: =IFERROR(__xludf.DUMMYFUNCTION("""COMPUTED_VALUE"""),183783.0) -> 183783 | N8: =IFERROR(__xludf.DUMMYFUNCTION("""COMPUTED_VALUE"""),10000.0) -> 10000 | O8: =IFERROR(__xludf.DUMMYFUNCTION("""COMPUTED_VALUE"""),3.6562969E7) -> 36562969 | P8: =IFERROR(__xludf.DUMMYFUNCTION("""COMPUTED_VALUE"""),"Toko Ladang") -> Toko Ladang | Q8: =IFERROR(__xludf.DUMMYFUNCTION("""COMPUTED_VALUE"""),"Pembayaran Diteruskan") -> Pembayaran Diteruskan | R8: =IFERROR(__xludf.DUMMYFUNCTION("""COMPUTED_VALUE"""),46248.59956018518) -> 46248.6 | S8: =IFERROR(__xludf.DUMMYFUNCTION("""COMPUTED_VALUE"""),"11282361/INV/PO6A7D702722CC2") -> 11282361/INV/PO6A7D702722CC2 | T8: =IFERROR(__xludf.DUMMYFUNCTION("""COMPUTED_VALUE"""),"PE-BYM-03") -> PE-BYM-03 | U8: =IFERROR(__xludf.DUMMYFUNCTION("""COMPUTED_VALUE"""),"11010202.2026.08.00001") -> 11010202.2026.08.00001 | W8: =IFERROR(__xludf.DUMMYFUNCTION("""COMPUTED_VALUE"""),3.66665E7) -> 36666500 | X8: =LEFT(H8,(LEN(H8)-19)) -> Kab. Banyumas
